## Docker commands used to build the application 
docker build -t techtrends .

## Docker commands used to run the application
docker run -d -p 7111:3111 techtrends

## Docker commands used to get the application logs
## get the container id
docker ps
## get the logs of this container id assigned to techtrends
docker logs -f 4e24945d609e

## Logs from the container running the TechTrends application
docker logs -f 4e24945d609e 

 * Serving Flask app 'app' (lazy loading)
 * Environment: production
   WARNING: This is a development server. Do not use it in a production deployment.
   Use a production WSGI server instead.
 * Debug mode: off
 * Running on all addresses.
   WARNING: This is a development server. Do not use it in a production deployment.
 * Running on http://172.17.0.2:3111/ (Press CTRL+C to quit)
[2023-02-27 13:12:44,164] ERROR in app: Exception on / [GET]
Traceback (most recent call last):
  File "/usr/local/lib/python3.8/site-packages/flask/app.py", line 2077, in wsgi_app
    response = self.full_dispatch_request()
  File "/usr/local/lib/python3.8/site-packages/flask/app.py", line 1525, in full_dispatch_request
    rv = self.handle_user_exception(e)
  File "/usr/local/lib/python3.8/site-packages/flask/app.py", line 1523, in full_dispatch_request
    rv = self.dispatch_request()
  File "/usr/local/lib/python3.8/site-packages/flask/app.py", line 1509, in dispatch_request
    return self.ensure_sync(self.view_functions[rule.endpoint])(**req.view_args)
  File "app.py", line 30, in index
    posts = connection.execute('SELECT * FROM posts').fetchall()
sqlite3.OperationalError: no such table: posts
172.17.0.1 - - [27/Feb/2023 13:12:44] "GET / HTTP/1.1" 500 -
172.17.0.1 - - [27/Feb/2023 13:12:44] "GET /favicon.ico HTTP/1.1" 404 -
[2023-02-27 13:15:42,264] ERROR in app: Exception on / [GET]
Traceback (most recent call last):
  File "/usr/local/lib/python3.8/site-packages/flask/app.py", line 2077, in wsgi_app
    response = self.full_dispatch_request()
  File "/usr/local/lib/python3.8/site-packages/flask/app.py", line 1525, in full_dispatch_request
    rv = self.handle_user_exception(e)
  File "/usr/local/lib/python3.8/site-packages/flask/app.py", line 1523, in full_dispatch_request
    rv = self.dispatch_request()
  File "/usr/local/lib/python3.8/site-packages/flask/app.py", line 1509, in dispatch_request
    return self.ensure_sync(self.view_functions[rule.endpoint])(**req.view_args)
  File "app.py", line 30, in index
    posts = connection.execute('SELECT * FROM posts').fetchall()
sqlite3.OperationalError: no such table: posts
172.17.0.1 - - [27/Feb/2023 13:15:42] "GET / HTTP/1.1" 500 -
[2023-02-27 13:21:13,362] ERROR in app: Exception on / [GET]
Traceback (most recent call last):
  File "/usr/local/lib/python3.8/site-packages/flask/app.py", line 2077, in wsgi_app
    response = self.full_dispatch_request()
  File "/usr/local/lib/python3.8/site-packages/flask/app.py", line 1525, in full_dispatch_request
    rv = self.handle_user_exception(e)
  File "/usr/local/lib/python3.8/site-packages/flask/app.py", line 1523, in full_dispatch_request
    rv = self.dispatch_request()
  File "/usr/local/lib/python3.8/site-packages/flask/app.py", line 1509, in dispatch_request
    return self.ensure_sync(self.view_functions[rule.endpoint])(**req.view_args)
  File "app.py", line 30, in index
    posts = connection.execute('SELECT * FROM posts').fetchall()
sqlite3.OperationalError: no such table: posts
172.17.0.1 - - [27/Feb/2023 13:21:13] "GET / HTTP/1.1" 500 -